<?xml version="1.0" encoding="utf-8"?>
<!-- This URDF was automatically created by SolidWorks to URDF Exporter! Originally created by Stephen Brawner (brawner@gmail.com) 
     Commit Version: 1.5.1-0-g916b5db  Build Version: 1.5.7152.31018
     For more information, please see http://wiki.ros.org/sw_urdf_exporter -->
<robot
  name="ROBOTIC ARM URDF ONLY">
  <link
    name="base_link">
    <inertial>
      <origin
        xyz="0.0130606856888135 0.104796725192401 0.133927940020527"
        rpy="0 0 0" />
      <mass
        value="1.3348146018366" />
      <inertia
        ixx="0.00731717119287839"
        ixy="-5.57214543565611E-19"
        ixz="7.11045805568132E-21"
        iyy="0.00731717119287839"
        iyz="-8.71309104260103E-20"
        izz="0.0135564188757262" />
    </inertial>
    <visual>
      <origin
        xyz="0 0 0"
        rpy="0 0 0" />
      <geometry>
        <mesh
          filename="package://ROBOTIC ARM URDF ONLY/meshes/base_link.STL" />
      </geometry>
      <material
        name="">
        <color
          rgba="0.792156862745098 0.819607843137255 0.933333333333333 1" />
      </material>
    </visual>
    <collision>
      <origin
        xyz="0 0 0"
        rpy="0 0 0" />
      <geometry>
        <mesh
          filename="package://ROBOTIC ARM URDF ONLY/meshes/base_link.STL" />
      </geometry>
    </collision>
  </link>
  <link
    name="rotating base">
    <inertial>
      <origin
        xyz="-0.00118830586385247 -0.000117561062136257 0.107080284193852"
        rpy="0 0 0" />
      <mass
        value="1.39759764473395" />
      <inertia
        ixx="0.00478115680882623"
        ixy="-0.000102672286793589"
        ixz="3.62391329450547E-05"
        iyy="0.00570738237120315"
        iyz="2.29069919150103E-06"
        izz="0.00576377931534605" />
    </inertial>
    <visual>
      <origin
        xyz="0 0 0"
        rpy="0 0 0" />
      <geometry>
        <mesh
          filename="package://ROBOTIC ARM URDF ONLY/meshes/rotating base.STL" />
      </geometry>
      <material
        name="">
        <color
          rgba="0.792156862745098 0.819607843137255 0.933333333333333 1" />
      </material>
    </visual>
    <collision>
      <origin
        xyz="0 0 0"
        rpy="0 0 0" />
      <geometry>
        <mesh
          filename="package://ROBOTIC ARM URDF ONLY/meshes/rotating base.STL" />
      </geometry>
    </collision>
  </link>
  <joint
    name="rotating base"
    type="fixed">
    <origin
      xyz="0.0130606856888136 -0.160303043320073 0.104796725192401"
      rpy="1.5707963267949 0 0" />
    <parent
      link="base_link" />
    <child
      link="rotating base" />
    <axis
      xyz="0 0 0" />
  </joint>
  <link
    name="lower arm">
    <inertial>
      <origin
        xyz="-0.128633379591227 -6.10622663543836E-16 -0.0583747798123898"
        rpy="0 0 0" />
      <mass
        value="0.325078566457199" />
      <inertia
        ixx="0.000884467798485974"
        ixy="-4.28673439826664E-06"
        ixz="9.33981049618837E-21"
        iyy="0.00203100229868317"
        iyz="-4.72914870430842E-19"
        izz="0.00126432994950172" />
    </inertial>
    <visual>
      <origin
        xyz="0 0 0"
        rpy="0 0 0" />
      <geometry>
        <mesh
          filename="package://ROBOTIC ARM URDF ONLY/meshes/lower arm.STL" />
      </geometry>
      <material
        name="">
        <color
          rgba="0.792156862745098 0.819607843137255 0.933333333333333 1" />
      </material>
    </visual>
    <collision>
      <origin
        xyz="0 0 0"
        rpy="0 0 0" />
      <geometry>
        <mesh
          filename="package://ROBOTIC ARM URDF ONLY/meshes/lower arm.STL" />
      </geometry>
    </collision>
  </link>
  <joint
    name="lower arm"
    type="fixed">
    <origin
      xyz="0.078904 0.035105 0.15625"
      rpy="1.5708 0.84817 1.6376" />
    <parent
      link="rotating base" />
    <child
      link="lower arm" />
    <axis
      xyz="0 0 0" />
  </joint>
  <link
    name="upper arm ">
    <inertial>
      <origin
        xyz="-0.0550000000000019 0.162571615295359 -0.0390699999999899"
        rpy="0 0 0" />
      <mass
        value="0.553932772437962" />
      <inertia
        ixx="0.00950068407154474"
        ixy="1.04244344818587E-16"
        ixz="3.37744895191354E-20"
        iyy="0.000128887101671353"
        iyz="1.55946605287555E-18"
        izz="0.00961971522402867" />
    </inertial>
    <visual>
      <origin
        xyz="0 0 0"
        rpy="0 0 0" />
      <geometry>
        <mesh
          filename="package://ROBOTIC ARM URDF ONLY/meshes/upper arm .STL" />
      </geometry>
      <material
        name="">
        <color
          rgba="0.792156862745098 0.819607843137255 0.933333333333333 1" />
      </material>
    </visual>
    <collision>
      <origin
        xyz="0 0 0"
        rpy="0 0 0" />
      <geometry>
        <mesh
          filename="package://ROBOTIC ARM URDF ONLY/meshes/upper arm .STL" />
      </geometry>
    </collision>
  </link>
  <joint
    name="upper arm"
    type="fixed">
    <origin
      xyz="-0.31117 0.029882 -0.09414"
      rpy="-3.1416 0 2.5672" />
    <parent
      link="lower arm" />
    <child
      link="upper arm " />
    <axis
      xyz="0 0 0" />
  </joint>
  <link
    name="upper wrist">
    <inertial>
      <origin
        xyz="-0.059900277561973 0.0145250651582457 -0.039069999999978"
        rpy="0 0 0" />
      <mass
        value="0.157249507163386" />
      <inertia
        ixx="0.000103336543586532"
        ixy="2.38357966733588E-05"
        ixz="1.33042038371679E-20"
        iyy="3.21046938039661E-05"
        iyz="3.51102052570133E-20"
        izz="0.000132196675957652" />
    </inertial>
    <visual>
      <origin
        xyz="0 0 0"
        rpy="0 0 0" />
      <geometry>
        <mesh
          filename="package://ROBOTIC ARM URDF ONLY/meshes/upper wrist.STL" />
      </geometry>
      <material
        name="">
        <color
          rgba="0.792156862745098 0.819607843137255 0.933333333333333 1" />
      </material>
    </visual>
    <collision>
      <origin
        xyz="0 0 0"
        rpy="0 0 0" />
      <geometry>
        <mesh
          filename="package://ROBOTIC ARM URDF ONLY/meshes/upper wrist.STL" />
      </geometry>
    </collision>
  </link>
  <joint
    name="upper wrist"
    type="fixed">
    <origin
      xyz="0 0.3712 0"
      rpy="0 0 0" />
    <parent
      link="upper arm " />
    <child
      link="upper wrist" />
    <axis
      xyz="0 0 0" />
  </joint>
  <link
    name="middle wrist">
    <inertial>
      <origin
        xyz="0.0650700000000001 -0.0896700233335407 -0.012715703160485"
        rpy="0 0 0" />
      <mass
        value="0.113820080301924" />
      <inertia
        ixx="1.80752904389812E-05"
        ixy="1.09279312925436E-18"
        ixz="-3.91482937563274E-19"
        iyy="7.58156761069057E-05"
        iyz="-1.86347248395946E-20"
        izz="8.93102953285944E-05" />
    </inertial>
    <visual>
      <origin
        xyz="0 0 0"
        rpy="0 0 0" />
      <geometry>
        <mesh
          filename="package://ROBOTIC ARM URDF ONLY/meshes/middle wrist.STL" />
      </geometry>
      <material
        name="">
        <color
          rgba="0.792156862745098 0.819607843137255 0.933333333333333 1" />
      </material>
    </visual>
    <collision>
      <origin
        xyz="0 0 0"
        rpy="0 0 0" />
      <geometry>
        <mesh
          filename="package://ROBOTIC ARM URDF ONLY/meshes/middle wrist.STL" />
      </geometry>
    </collision>
  </link>
  <joint
    name="middle wrist"
    type="fixed">
    <origin
      xyz="-0.032259 0.007672 -0.10414"
      rpy="-1.3607 -1.5708 -1.4557" />
    <parent
      link="upper wrist" />
    <child
      link="middle wrist" />
    <axis
      xyz="0 0 0" />
  </joint>
  <link
    name="lower wrist">
    <inertial>
      <origin
        xyz="-1.73069891751254E-13 0.0112725620294346 0.0238188793866976"
        rpy="0 0 0" />
      <mass
        value="0.0521786415366043" />
      <inertia
        ixx="2.40049687608685E-05"
        ixy="-2.96461266841209E-17"
        ixz="3.84550559229676E-18"
        iyy="4.35494931309566E-05"
        iyz="-3.42527115552258E-06"
        izz="2.46186676394023E-05" />
    </inertial>
    <visual>
      <origin
        xyz="0 0 0"
        rpy="0 0 0" />
      <geometry>
        <mesh
          filename="package://ROBOTIC ARM URDF ONLY/meshes/lower wrist.STL" />
      </geometry>
      <material
        name="">
        <color
          rgba="0.792156862745098 0.819607843137255 0.933333333333333 1" />
      </material>
    </visual>
    <collision>
      <origin
        xyz="0 0 0"
        rpy="0 0 0" />
      <geometry>
        <mesh
          filename="package://ROBOTIC ARM URDF ONLY/meshes/lower wrist.STL" />
      </geometry>
    </collision>
  </link>
  <joint
    name="lower wrist"
    type="continuous">
    <origin
      xyz="0.06507 -0.11943 -0.01"
      rpy="-1.5708 0.010999 3.1416" />
    <parent
      link="middle wrist" />
    <child
      link="lower wrist" />
    <axis
      xyz="0 0 1" />
  </joint>
  <link
    name="end effector">
    <inertial>
      <origin
        xyz="0.0220101986822902 -0.00839778572417443 -0.0251828532394619"
        rpy="0 0 0" />
      <mass
        value="0.0176722137375323" />
      <inertia
        ixx="2.08105506846894E-06"
        ixy="7.8490913868189E-08"
        ixz="-2.53468984637684E-18"
        iyy="1.42701843774076E-06"
        iyz="-5.05546320612809E-19"
        izz="3.48089604018252E-06" />
    </inertial>
    <visual>
      <origin
        xyz="0 0 0"
        rpy="0 0 0" />
      <geometry>
        <mesh
          filename="package://ROBOTIC ARM URDF ONLY/meshes/end effector.STL" />
      </geometry>
      <material
        name="">
        <color
          rgba="0.792156862745098 0.819607843137255 0.933333333333333 1" />
      </material>
    </visual>
    <collision>
      <origin
        xyz="0 0 0"
        rpy="0 0 0" />
      <geometry>
        <mesh
          filename="package://ROBOTIC ARM URDF ONLY/meshes/end effector.STL" />
      </geometry>
    </collision>
  </link>
  <joint
    name="end effector"
    type="continuous">
    <origin
      xyz="0.02 -0.010879 0.035374"
      rpy="-1.5708 -0.2079 3.1416" />
    <parent
      link="lower wrist" />
    <child
      link="end effector" />
    <axis
      xyz="0 0 1" />
  </joint>
</robot>