<?xml version="1.0" encoding="utf-8"?>
<!-- This URDF was automatically created by SolidWorks to URDF Exporter! Originally created by Stephen Brawner (brawner@gmail.com) 
     Commit Version: 1.5.1-0-g916b5db  Build Version: 1.5.7152.31018
     For more information, please see http://wiki.ros.org/sw_urdf_exporter -->
<robot
  name="RobotArmUrdfMeshesProp">
  <link
    name="base_link">
    <inertial>
      <origin
        xyz="0.0130606856888135 -0.133927940020527 0.104796725192401"
        rpy="0 0 0" />
      <mass
        value="1.3348146018366" />
      <inertia
        ixx="0.00731717119287839"
        ixy="-7.11045805568136E-21"
        ixz="-5.57214543565611E-19"
        iyy="0.0135564188757262"
        iyz="-2.94900207348336E-19"
        izz="0.00731717119287839" />
    </inertial>
    <visual>
      <origin
        xyz="0 0 0"
        rpy="0 0 0" />
      <geometry>
        <mesh
          filename="package://RobotArmUrdfMeshesProp/meshes/base_link.STL" />
      </geometry>
      <material
        name="">
        <color
          rgba="0.792156862745098 0.819607843137255 0.933333333333333 1" />
      </material>
    </visual>
    <collision>
      <origin
        xyz="0 0 0"
        rpy="0 0 0" />
      <geometry>
        <mesh
          filename="package://RobotArmUrdfMeshesProp/meshes/base_link.STL" />
      </geometry>
    </collision>
  </link>
  <link
    name="rotating base">
    <inertial>
      <origin
        xyz="-0.00118830586385247 -0.00011756106213627 0.107080284193852"
        rpy="0 0 0" />
      <mass
        value="1.39759764473395" />
      <inertia
        ixx="0.00478115680882623"
        ixy="-0.000102672286793589"
        ixz="3.62391329450548E-05"
        iyy="0.00570738237120315"
        iyz="2.29069919150106E-06"
        izz="0.00576377931534605" />
    </inertial>
    <visual>
      <origin
        xyz="0 0 0"
        rpy="0 0 0" />
      <geometry>
        <mesh
          filename="package://RobotArmUrdfMeshesProp/meshes/rotating base.STL" />
      </geometry>
      <material
        name="">
        <color
          rgba="0.792156862745098 0.819607843137255 0.933333333333333 1" />
      </material>
    </visual>
    <collision>
      <origin
        xyz="0 0 0"
        rpy="0 0 0" />
      <geometry>
        <mesh
          filename="package://RobotArmUrdfMeshesProp/meshes/rotating base.STL" />
      </geometry>
    </collision>
  </link>
  <joint
    name="rotating base"
    type="fixed">
    <origin
      xyz="0.0130606856888136 -0.160303043320073 0.104796725192401"
      rpy="1.5707963267949 0 0" />
    <parent
      link="base_link" />
    <child
      link="rotating base" />
    <axis
      xyz="0 0 0" />
  </joint>
  <link
    name="lower arm">
    <inertial>
      <origin
        xyz="-0.128633379591227 -6.66133814775094E-16 -0.0583747798123898"
        rpy="0 0 0" />
      <mass
        value="0.325078566457199" />
      <inertia
        ixx="0.000884467798485973"
        ixy="-4.28673439826683E-06"
        ixz="-7.53664330905173E-20"
        iyy="0.00203100229868317"
        iyz="-4.46025752126274E-19"
        izz="0.00126432994950172" />
    </inertial>
    <visual>
      <origin
        xyz="0 0 0"
        rpy="0 0 0" />
      <geometry>
        <mesh
          filename="package://RobotArmUrdfMeshesProp/meshes/lower arm.STL" />
      </geometry>
      <material
        name="">
        <color
          rgba="0.792156862745098 0.819607843137255 0.933333333333333 1" />
      </material>
    </visual>
    <collision>
      <origin
        xyz="0 0 0"
        rpy="0 0 0" />
      <geometry>
        <mesh
          filename="package://RobotArmUrdfMeshesProp/meshes/lower arm.STL" />
      </geometry>
    </collision>
  </link>
  <joint
    name="lower arm"
    type="fixed">
    <origin
      xyz="0.0789039407101542 0.0351054747045865 0.156246736186644"
      rpy="1.5707963267949 0.848171739621261 1.63758786604713" />
    <parent
      link="rotating base" />
    <child
      link="lower arm" />
    <axis
      xyz="0 0 0" />
  </joint>
  <link
    name="upper arm ">
    <inertial>
      <origin
        xyz="-0.0550000000000022 0.162571615295359 -0.0390699999999894"
        rpy="0 0 0" />
      <mass
        value="0.553932772437962" />
      <inertia
        ixx="0.00950068407154474"
        ixy="1.04469655582556E-16"
        ixz="4.74013502241347E-20"
        iyy="0.000128887101671353"
        iyz="1.29334379984524E-18"
        izz="0.00961971522402867" />
    </inertial>
    <visual>
      <origin
        xyz="0 0 0"
        rpy="0 0 0" />
      <geometry>
        <mesh
          filename="package://RobotArmUrdfMeshesProp/meshes/upper arm .STL" />
      </geometry>
      <material
        name="">
        <color
          rgba="0.792156862745098 0.819607843137255 0.933333333333333 1" />
      </material>
    </visual>
    <collision>
      <origin
        xyz="0 0 0"
        rpy="0 0 0" />
      <geometry>
        <mesh
          filename="package://RobotArmUrdfMeshesProp/meshes/upper arm .STL" />
      </geometry>
    </collision>
  </link>
  <joint
    name="upper arm"
    type="fixed">
    <origin
      xyz="-0.311174431281137 0.029881798738756 -0.0941399999999955"
      rpy="-3.14159265358979 0 2.56722332066206" />
    <parent
      link="lower arm" />
    <child
      link="upper arm " />
    <axis
      xyz="0 0 0" />
  </joint>
  <link
    name="upper wrist">
    <inertial>
      <origin
        xyz="-0.0599002775619729 0.0145250651582456 -0.039069999999978"
        rpy="0 0 0" />
      <mass
        value="0.157249507163386" />
      <inertia
        ixx="0.000103336543586532"
        ixy="2.38357966733588E-05"
        ixz="1.28806873635407E-20"
        iyy="3.21046938039661E-05"
        iyz="3.81806996908101E-20"
        izz="0.000132196675957652" />
    </inertial>
    <visual>
      <origin
        xyz="0 0 0"
        rpy="0 0 0" />
      <geometry>
        <mesh
          filename="package://RobotArmUrdfMeshesProp/meshes/upper wrist.STL" />
      </geometry>
      <material
        name="">
        <color
          rgba="0.792156862745098 0.819607843137255 0.933333333333333 1" />
      </material>
    </visual>
    <collision>
      <origin
        xyz="0 0 0"
        rpy="0 0 0" />
      <geometry>
        <mesh
          filename="package://RobotArmUrdfMeshesProp/meshes/upper wrist.STL" />
      </geometry>
    </collision>
  </link>
  <joint
    name="upper wrist"
    type="fixed">
    <origin
      xyz="0 0.371200669102145 0"
      rpy="0 0 0" />
    <parent
      link="upper arm " />
    <child
      link="upper wrist" />
    <axis
      xyz="0 0 0" />
  </joint>
  <link
    name="middle wrist">
    <inertial>
      <origin
        xyz="0.0650700000000001 -0.0896700233335407 -0.012715703160485"
        rpy="0 0 0" />
      <mass
        value="0.113820080301924" />
      <inertia
        ixx="1.80752904389812E-05"
        ixy="1.09142836042383E-18"
        ixz="-3.91325154184438E-19"
        iyy="7.58156761069057E-05"
        iyz="-2.03287907341032E-20"
        izz="8.93102953285944E-05" />
    </inertial>
    <visual>
      <origin
        xyz="0 0 0"
        rpy="0 0 0" />
      <geometry>
        <mesh
          filename="package://RobotArmUrdfMeshesProp/meshes/middle wrist.STL" />
      </geometry>
      <material
        name="">
        <color
          rgba="0.792156862745098 0.819607843137255 0.933333333333333 1" />
      </material>
    </visual>
    <collision>
      <origin
        xyz="0 0 0"
        rpy="0 0 0" />
      <geometry>
        <mesh
          filename="package://RobotArmUrdfMeshesProp/meshes/middle wrist.STL" />
      </geometry>
    </collision>
  </link>
  <joint
    name="middle wrist"
    type="fixed">
    <origin
      xyz="-0.0322592690294007 0.00767197203615905 -0.104139999999975"
      rpy="-1.36065826757667 -1.57079631189374 -1.45573033079862" />
    <parent
      link="upper wrist" />
    <child
      link="middle wrist" />
    <axis
      xyz="0 0 0" />
  </joint>
  <link
    name="lower wrist">
    <inertial>
      <origin
        xyz="1.34718625144359E-13 0.0112725620294538 0.0238188793866976"
        rpy="0 0 0" />
      <mass
        value="0.0521786415366043" />
      <inertia
        ixx="2.40049687608685E-05"
        ixy="-3.92310191663526E-17"
        ixz="5.54238555524927E-18"
        iyy="4.35494931309565E-05"
        iyz="-3.42527115552257E-06"
        izz="2.46186676394022E-05" />
    </inertial>
    <visual>
      <origin
        xyz="0 0 0"
        rpy="0 0 0" />
      <geometry>
        <mesh
          filename="package://RobotArmUrdfMeshesProp/meshes/lower wrist.STL" />
      </geometry>
      <material
        name="">
        <color
          rgba="0.792156862745098 0.819607843137255 0.933333333333333 1" />
      </material>
    </visual>
    <collision>
      <origin
        xyz="0 0 0"
        rpy="0 0 0" />
      <geometry>
        <mesh
          filename="package://RobotArmUrdfMeshesProp/meshes/lower wrist.STL" />
      </geometry>
    </collision>
  </link>
  <joint
    name="lower wrist"
    type="continuous">
    <origin
      xyz="0.0650700000000014 -0.119432096019538 -0.00999999999999968"
      rpy="-1.5707963267949 0.0109990775981734 3.14159265358977" />
    <parent
      link="middle wrist" />
    <child
      link="lower wrist" />
    <axis
      xyz="0 0 1" />
  </joint>
  <link
    name="end effector">
    <inertial>
      <origin
        xyz="0.022010198682042 -0.00839778572424027 -0.0251828532394741"
        rpy="0 0 0" />
      <mass
        value="0.0176722137375322" />
      <inertia
        ixx="2.0810550684685E-06"
        ixy="7.84909138683308E-08"
        ixz="-2.74615360689235E-18"
        iyy="1.4270184377412E-06"
        iyz="-7.14684049245816E-19"
        izz="3.48089604018252E-06" />
    </inertial>
    <visual>
      <origin
        xyz="0 0 0"
        rpy="0 0 0" />
      <geometry>
        <mesh
          filename="package://RobotArmUrdfMeshesProp/meshes/end effector.STL" />
      </geometry>
      <material
        name="">
        <color
          rgba="0.792156862745098 0.819607843137255 0.933333333333333 1" />
      </material>
    </visual>
    <collision>
      <origin
        xyz="0 0 0"
        rpy="0 0 0" />
      <geometry>
        <mesh
          filename="package://RobotArmUrdfMeshesProp/meshes/end effector.STL" />
      </geometry>
    </collision>
  </link>
  <joint
    name="end effector"
    type="continuous">
    <origin
      xyz="0.020000000000215 -0.010878906011115 0.0353739216947843"
      rpy="-1.5707963267949 -0.207904224454029 3.14159265358979" />
    <parent
      link="lower wrist" />
    <child
      link="end effector" />
    <axis
      xyz="0 0 1" />
  </joint>
</robot>